Traceback (most recent call last):
  File "/Users/mriki/.pyenv/versions/miniforge3-4.10.3-10/envs/datasci/lib/python3.10/site-packages/jupyter_cache/executors/utils.py", line 58, in single_nb_execution
    executenb(
  File "/Users/mriki/.pyenv/versions/miniforge3-4.10.3-10/envs/datasci/lib/python3.10/site-packages/nbclient/client.py", line 1204, in execute
    return NotebookClient(nb=nb, resources=resources, km=km, **kwargs).execute()
  File "/Users/mriki/.pyenv/versions/miniforge3-4.10.3-10/envs/datasci/lib/python3.10/site-packages/nbclient/util.py", line 84, in wrapped
    return just_run(coro(*args, **kwargs))
  File "/Users/mriki/.pyenv/versions/miniforge3-4.10.3-10/envs/datasci/lib/python3.10/site-packages/nbclient/util.py", line 62, in just_run
    return loop.run_until_complete(coro)
  File "/Users/mriki/.pyenv/versions/miniforge3-4.10.3-10/envs/datasci/lib/python3.10/asyncio/base_events.py", line 646, in run_until_complete
    return future.result()
  File "/Users/mriki/.pyenv/versions/miniforge3-4.10.3-10/envs/datasci/lib/python3.10/site-packages/nbclient/client.py", line 663, in async_execute
    await self.async_execute_cell(
  File "/Users/mriki/.pyenv/versions/miniforge3-4.10.3-10/envs/datasci/lib/python3.10/site-packages/nbclient/client.py", line 965, in async_execute_cell
    await self._check_raise_for_error(cell, cell_index, exec_reply)
  File "/Users/mriki/.pyenv/versions/miniforge3-4.10.3-10/envs/datasci/lib/python3.10/site-packages/nbclient/client.py", line 862, in _check_raise_for_error
    raise CellExecutionError.from_cell_and_msg(cell, exec_reply_content)
nbclient.exceptions.CellExecutionError: An error occurred while executing the following cell:
------------------
BS = 2
dataset = MyDataset(make_word2id_seq(texts, word2id))
dl = DataLoader(dataset, batch_size=BS, shuffle=True, drop_last=True)
iterator = iter(dl)
X_train, y_train = next(iterator)
print(X_train.shape)
print(X_train)
print(y_train.shape)
print(y_train)
------------------

[0;31m---------------------------------------------------------------------------[0m
[0;31mNameError[0m                                 Traceback (most recent call last)
Cell [0;32mIn[8], line 2[0m
[1;32m      1[0m BS [38;5;241m=[39m [38;5;241m2[39m
[0;32m----> 2[0m dataset [38;5;241m=[39m MyDataset([43mmake_word2id_seq[49m(texts, word2id))
[1;32m      3[0m dl [38;5;241m=[39m DataLoader(dataset, batch_size[38;5;241m=[39mBS, shuffle[38;5;241m=[39m[38;5;28;01mTrue[39;00m, drop_last[38;5;241m=[39m[38;5;28;01mTrue[39;00m)
[1;32m      4[0m iterator [38;5;241m=[39m [38;5;28miter[39m(dl)

[0;31mNameError[0m: name 'make_word2id_seq' is not defined
NameError: name 'make_word2id_seq' is not defined

